2024-09-17 11:16:18,033 - [INFO]: loaded dotenv
2024-09-17 11:16:18,033 - [INFO]: bot starting... please hold on for a moment...
2024-09-17 11:16:18,034 - [WARNING]: PyNaCl is not installed, voice will NOT be supported
2024-09-17 11:16:18,041 - [INFO]: logging in using static token
2024-09-17 11:16:18,834 - [INFO]: Shard ID None has sent the IDENTIFY payload.
2024-09-17 11:16:19,156 - [INFO]: Shard ID None has connected to Gateway: ["gateway-prd-us-east1-d-20hd",{"micros":71515,"calls":["id_created",{"micros":783,"calls":[]},"session_lookup_time",{"micros":240,"calls":[]},"session_lookup_finished",{"micros":18,"calls":[]},"discord-sessions-prd-1-135",{"micros":70243,"calls":["start_session",{"micros":39753,"calls":["discord-api-rpc-6b74d57658-c8qxh",{"micros":35726,"calls":["get_user",{"micros":4839},"get_guilds",{"micros":3284},"send_scheduled_deletion_message",{"micros":8},"guild_join_requests",{"micros":241},"authorized_ip_coro",{"micros":8}]}]},"starting_guild_connect",{"micros":60,"calls":[]},"presence_started",{"micros":324,"calls":[]},"guilds_started",{"micros":86,"calls":[]},"guilds_connect",{"micros":2,"calls":[]},"presence_connect",{"micros":29969,"calls":[]},"connect_finished",{"micros":29974,"calls":[]},"build_ready",{"micros":40,"calls":[]},"clean_ready",{"micros":1,"calls":[]},"optimize_ready",{"micros":0,"calls":[]},"split_ready",{"micros":1,"calls":[]}]}]}] (Session ID: 8a04e50a161f4f7d52cf1ff45f7ff625).
2024-09-17 11:16:21,162 - [INFO]: Logged in as z_#2304
2024-09-17 11:16:21,162 - [INFO]: Bot is running!! Have fun!! :3
2024-09-17 11:16:21,162 - [INFO]: Clearing rate limits.
2024-09-17 11:16:21,162 - [WARNING]: rate.json either does not exist or is not initialized.
2024-09-17 11:16:21,162 - [INFO]: initializing rate.json
2024-09-17 11:16:21,163 - [ERROR]: Task exception was never retrieved
future: <Task finished name='Task-13' coro=<clear_rate() done, defined at /Users/nat/HOME/arg/main.py:61> exception=ValueError('I/O operation on closed file.')>
Traceback (most recent call last):
  File "/Users/nat/HOME/arg/main.py", line 29, in loadjson
    with open(filename, "r") as file:
         ^^^^^^^^^^^^^^^^^^^
FileNotFoundError: [Errno 2] No such file or directory: 'rate.json'

During handling of the above exception, another exception occurred:

Traceback (most recent call last):
  File "/Users/nat/HOME/arg/main.py", line 65, in clear_rate
    data = loadjson("rate.json")
           ^^^^^^^^^^^^^^^^^^^^^
  File "/Users/nat/HOME/arg/main.py", line 36, in loadjson
    return json.load(file)
           ^^^^^^^^^^^^^^^
  File "/opt/homebrew/Cellar/python@3.12/3.12.5/Frameworks/Python.framework/Versions/3.12/lib/python3.12/json/__init__.py", line 293, in load
    return loads(fp.read(),
                 ^^^^^^^^^
ValueError: I/O operation on closed file.
